<?xml version="1.0" encoding="utf-8"?>
<!-- This URDF was automatically created by SolidWorks to URDF Exporter! Originally created by Stephen Brawner (brawner@gmail.com) 
     Commit Version: 1.6.0-4-g7f85cfe  Build Version: 1.6.7995.38578
     For more information, please see http://wiki.ros.org/sw_urdf_exporter -->
<robot
  name="4090_3.0_12_6">
  <link
    name="BASE">
    <inertial>
      <origin
        xyz="0.20011825293162 2.31310424497672E-07 0.0527224714838719"
        rpy="0 0 0" />
      <mass
        value="7.44160057363593" />
      <inertia
        ixx="0.550673341430934"
        ixy="-1.38784303146432E-07"
        ixz="8.47301816983124E-06"
        iyy="0.102252370093071"
        iyz="-3.46679843446467E-08"
        izz="0.642667087930141" />
    </inertial>
    <visual>
      <origin
        xyz="0 0 0"
        rpy="0 0 0" />
      <geometry>
        <mesh
          filename="package://4090_3.0_12_6/meshes/BASE.STL" />
      </geometry>
      <material
        name="">
        <color
          rgba="0.866666666666667 0.909803921568627 1 1" />
      </material>
    </visual>
    <collision>
      <origin
        xyz="0 0 0"
        rpy="0 0 0" />
      <geometry>
        <mesh
          filename="package://4090_3.0_12_6/meshes/BASE.STL" />
      </geometry>
    </collision>
  </link>
  <link
    name="RF_HIP">
    <inertial>
      <origin
        xyz="-0.02841 -0.0013383 0.10482"
        rpy="0 0 0" />
      <mass
        value="1.1161" />
      <inertia
        ixx="0.0013596"
        ixy="-3.0591E-05"
        ixz="0.00022242"
        iyy="0.0021096"
        iyz="1.3892E-05"
        izz="0.0016645" />
    </inertial>
    <visual>
      <origin
        xyz="0 0 0"
        rpy="0 0 0" />
      <geometry>
        <mesh
          filename="package://4090_3.0_12_6/meshes/RF_HIP.STL" />
      </geometry>
      <material
        name="">
        <color
          rgba="0.75294 0.75294 0.75294 1" />
      </material>
    </visual>
    <collision>
      <origin
        xyz="0 0 0"
        rpy="0 0 0" />
      <geometry>
        <mesh
          filename="package://4090_3.0_12_6/meshes/RF_HIP.STL" />
      </geometry>
    </collision>
  </link>
  <joint
    name="RF_HAA"
    type="revolute">
    <origin
      xyz="0.1 -0.45 0.0895"
      rpy="3.1416 0 0" />
    <parent
      link="BASE" />
    <child
      link="RF_HIP" />
    <axis
      xyz="0 0 1" />
    <limit
      lower="-3"
      upper="3"
      effort="80"
      velocity="15.8" />
  </joint>
  <link
    name="RF_THIGH">
    <inertial>
      <origin
        xyz="-0.0284793857778061 0.0124922843671791 -0.0809891914111928"
        rpy="0 0 0" />
      <mass
        value="1.00124210184093" />
      <inertia
        ixx="0.00104777246852464"
        ixy="0.00092923152965928"
        ixz="2.63860464845249E-05"
        iyy="0.00212933827797083"
        iyz="-1.15742003555609E-05"
        izz="0.0028121199978105" />
    </inertial>
    <visual>
      <origin
        xyz="0 0 0"
        rpy="0 0 0" />
      <geometry>
        <mesh
          filename="package://4090_3.0_12_6/meshes/RF_THIGH.STL" />
      </geometry>
      <material
        name="">
        <color
          rgba="0.752941176470588 0.752941176470588 0.752941176470588 1" />
      </material>
    </visual>
    <collision>
      <origin
        xyz="0 0 0"
        rpy="0 0 0" />
      <geometry>
        <mesh
          filename="package://4090_3.0_12_6/meshes/RF_THIGH.STL" />
      </geometry>
    </collision>
  </link>
  <joint
    name="RF_HFE"
    type="revolute">
    <origin
      xyz="-0.09 0.0795 0.154"
      rpy="-1.5708 0 0" />
    <parent
      link="RF_HIP" />
    <child
      link="RF_THIGH" />
    <axis
      xyz="0 0 1" />
    <limit
      lower="0"
      upper="0"
      effort="0"
      velocity="0" />
  </joint>
  <link
    name="RF_SHANK">
    <inertial>
      <origin
        xyz="-0.00122265540921057 -0.107332155640051 -0.0108827996779151"
        rpy="0 0 0" />
      <mass
        value="0.577673514828141" />
      <inertia
        ixx="0.00449636142962496"
        ixy="-5.31534442939036E-05"
        ixz="1.14279201092476E-08"
        iyy="6.70982844119264E-05"
        iyz="2.41776164816069E-06"
        izz="0.00452066750610663" />
    </inertial>
    <visual>
      <origin
        xyz="0 0 0"
        rpy="0 0 0" />
      <geometry>
        <mesh
          filename="package://4090_3.0_12_6/meshes/RF_SHANK.STL" />
      </geometry>
      <material
        name="">
        <color
          rgba="0.752941176470588 0.752941176470588 0.752941176470588 1" />
      </material>
    </visual>
    <collision>
      <origin
        xyz="0 0 0"
        rpy="0 0 0" />
      <geometry>
        <mesh
          filename="package://4090_3.0_12_6/meshes/RF_SHANK.STL" />
      </geometry>
    </collision>
  </link>
  <joint
    name="RF_KFE"
    type="revolute">
    <origin
      xyz="-0.1782 0.090798 -0.0685"
      rpy="0 0 0" />
    <parent
      link="RF_THIGH" />
    <child
      link="RF_SHANK" />
    <axis
      xyz="0 0 1" />
    <limit
      lower="0"
      upper="0"
      effort="0"
      velocity="0" />
  </joint>
  <link
    name="RF_FOOT">
    <inertial>
      <origin
        xyz="0.00315049033376028 0.0187638839574205 0.000250412469435857"
        rpy="0 0 0" />
      <mass
        value="0.0652350471365656" />
      <inertia
        ixx="1.21479534427067E-05"
        ixy="-6.01498264007157E-08"
        ixz="2.79521528852395E-08"
        iyy="1.32089620990545E-05"
        iyz="-9.55458698113226E-08"
        izz="1.43072768151951E-05" />
    </inertial>
    <visual>
      <origin
        xyz="0 0 0"
        rpy="0 0 0" />
      <geometry>
        <mesh
          filename="package://4090_3.0_12_6/meshes/RF_FOOT.STL" />
      </geometry>
      <material
        name="">
        <color
          rgba="0.501960784313725 0.501960784313725 0.752941176470588 1" />
      </material>
    </visual>
    <collision>
      <origin
        xyz="0 0 0"
        rpy="0 0 0" />
      <geometry>
        <mesh
          filename="package://4090_3.0_12_6/meshes/RF_FOOT.STL" />
      </geometry>
    </collision>
  </link>
  <joint
    name="RF_FIX"
    type="fixed">
    <origin
      xyz="-0.0081826 -0.29917 -0.011107"
      rpy="0 0 0" />
    <parent
      link="RF_SHANK" />
    <child
      link="RF_FOOT" />
    <axis
      xyz="0 0 0" />
  </joint>
  <link
    name="RM_HIP">
    <inertial>
      <origin
        xyz="-0.02841 -0.0013382 0.10482"
        rpy="0 0 0" />
      <mass
        value="1.1161" />
      <inertia
        ixx="0.0013596"
        ixy="-3.06E-05"
        ixz="0.00022242"
        iyy="0.0021096"
        iyz="1.3892E-05"
        izz="0.0016645" />
    </inertial>
    <visual>
      <origin
        xyz="0 0 0"
        rpy="0 0 0" />
      <geometry>
        <mesh
          filename="package://4090_3.0_12_6/meshes/RM_HIP.STL" />
      </geometry>
      <material
        name="">
        <color
          rgba="0.75294 0.75294 0.75294 1" />
      </material>
    </visual>
    <collision>
      <origin
        xyz="0 0 0"
        rpy="0 0 0" />
      <geometry>
        <mesh
          filename="package://4090_3.0_12_6/meshes/RM_HIP.STL" />
      </geometry>
    </collision>
  </link>
  <joint
    name="RM_HAA"
    type="revolute">
    <origin
      xyz="0 0 0.0895"
      rpy="3.1416 0 0" />
    <parent
      link="BASE" />
    <child
      link="RM_HIP" />
    <axis
      xyz="0 0 1" />
    <limit
      lower="0"
      upper="0"
      effort="0"
      velocity="0" />
  </joint>
  <link
    name="RM_THIGH">
    <inertial>
      <origin
        xyz="-0.028479 0.012492 -0.080989"
        rpy="0 0 0" />
      <mass
        value="1.0012" />
      <inertia
        ixx="0.0010478"
        ixy="0.00092923"
        ixz="2.6386E-05"
        iyy="0.0021293"
        iyz="-1.1574E-05"
        izz="0.0028121" />
    </inertial>
    <visual>
      <origin
        xyz="0 0 0"
        rpy="0 0 0" />
      <geometry>
        <mesh
          filename="package://4090_3.0_12_6/meshes/RM_THIGH.STL" />
      </geometry>
      <material
        name="">
        <color
          rgba="0.75294 0.75294 0.75294 1" />
      </material>
    </visual>
    <collision>
      <origin
        xyz="0 0 0"
        rpy="0 0 0" />
      <geometry>
        <mesh
          filename="package://4090_3.0_12_6/meshes/RM_THIGH.STL" />
      </geometry>
    </collision>
  </link>
  <joint
    name="RM_HFE"
    type="revolute">
    <origin
      xyz="-0.09 0.0795 0.154"
      rpy="-1.5708 0 0" />
    <parent
      link="RM_HIP" />
    <child
      link="RM_THIGH" />
    <axis
      xyz="0 0 1" />
    <limit
      lower="0"
      upper="0"
      effort="0"
      velocity="0" />
  </joint>
  <link
    name="RM_SHANK">
    <inertial>
      <origin
        xyz="-0.00122265540921052 -0.107332155640051 -0.0108827996779151"
        rpy="0 0 0" />
      <mass
        value="0.577673514828141" />
      <inertia
        ixx="0.00449636142962497"
        ixy="-5.31534442939036E-05"
        ixz="1.14279201092382E-08"
        iyy="6.70982844119265E-05"
        iyz="2.41776164816309E-06"
        izz="0.00452066750610663" />
    </inertial>
    <visual>
      <origin
        xyz="0 0 0"
        rpy="0 0 0" />
      <geometry>
        <mesh
          filename="package://4090_3.0_12_6/meshes/RM_SHANK.STL" />
      </geometry>
      <material
        name="">
        <color
          rgba="0.752941176470588 0.752941176470588 0.752941176470588 1" />
      </material>
    </visual>
    <collision>
      <origin
        xyz="0 0 0"
        rpy="0 0 0" />
      <geometry>
        <mesh
          filename="package://4090_3.0_12_6/meshes/RM_SHANK.STL" />
      </geometry>
    </collision>
  </link>
  <joint
    name="RM_KFE"
    type="revolute">
    <origin
      xyz="-0.1782 0.090798 -0.0685"
      rpy="0 0 0" />
    <parent
      link="RM_THIGH" />
    <child
      link="RM_SHANK" />
    <axis
      xyz="0 0 1" />
    <limit
      lower="0"
      upper="0"
      effort="0"
      velocity="0" />
  </joint>
  <link
    name="RM_FOOT">
    <inertial>
      <origin
        xyz="0.00315050745146095 0.0187638697177974 0.00025045316141364"
        rpy="0 0 0" />
      <mass
        value="0.0652348178450878" />
      <inertia
        ixx="1.21479077971544E-05"
        ixy="-6.01584074528566E-08"
        ixz="2.79648715833423E-08"
        iyy="1.32089245638991E-05"
        iyz="-9.55662024543555E-08"
        izz="1.43072591990465E-05" />
    </inertial>
    <visual>
      <origin
        xyz="0 0 0"
        rpy="0 0 0" />
      <geometry>
        <mesh
          filename="package://4090_3.0_12_6/meshes/RM_FOOT.STL" />
      </geometry>
      <material
        name="">
        <color
          rgba="0.501960784313725 0.501960784313725 0.752941176470588 1" />
      </material>
    </visual>
    <collision>
      <origin
        xyz="0 0 0"
        rpy="0 0 0" />
      <geometry>
        <mesh
          filename="package://4090_3.0_12_6/meshes/RM_FOOT.STL" />
      </geometry>
    </collision>
  </link>
  <joint
    name="RM_FIX"
    type="fixed">
    <origin
      xyz="-0.0081826 -0.29917 -0.011107"
      rpy="0 0 0" />
    <parent
      link="RM_SHANK" />
    <child
      link="RM_FOOT" />
    <axis
      xyz="0 0 0" />
  </joint>
  <link
    name="RB_HIP">
    <inertial>
      <origin
        xyz="-0.02841 0.0013388 0.10452"
        rpy="0 0 0" />
      <mass
        value="1.1161" />
      <inertia
        ixx="0.0013596"
        ixy="3.0609E-05"
        ixz="0.00022242"
        iyy="0.0021096"
        iyz="-1.3892E-05"
        izz="0.0016645" />
    </inertial>
    <visual>
      <origin
        xyz="0 0 0"
        rpy="0 0 0" />
      <geometry>
        <mesh
          filename="package://4090_3.0_12_6/meshes/RB_HIP.STL" />
      </geometry>
      <material
        name="">
        <color
          rgba="0.75294 0.75294 0.75294 1" />
      </material>
    </visual>
    <collision>
      <origin
        xyz="0 0 0"
        rpy="0 0 0" />
      <geometry>
        <mesh
          filename="package://4090_3.0_12_6/meshes/RB_HIP.STL" />
      </geometry>
    </collision>
  </link>
  <joint
    name="RB_HAA"
    type="revolute">
    <origin
      xyz="0.1 0.45 0.0892"
      rpy="3.1416 0 0" />
    <parent
      link="BASE" />
    <child
      link="RB_HIP" />
    <axis
      xyz="0 0 1" />
    <limit
      lower="0"
      upper="0"
      effort="0"
      velocity="0" />
  </joint>
  <link
    name="RB_THIGH">
    <inertial>
      <origin
        xyz="-0.0204950680459353 0.00899001882019033 -0.0830411129441901"
        rpy="0 0 0" />
      <mass
        value="1.39129865389905" />
      <inertia
        ixx="0.00139954951211599"
        ixy="0.000929231486131266"
        ixz="-2.63860335970541E-05"
        iyy="0.00248111523541319"
        iyz="1.1574186831828E-05"
        izz="0.00347348329678469" />
    </inertial>
    <visual>
      <origin
        xyz="0 0 0"
        rpy="0 0 0" />
      <geometry>
        <mesh
          filename="package://4090_3.0_12_6/meshes/RB_THIGH.STL" />
      </geometry>
      <material
        name="">
        <color
          rgba="0.752941176470588 0.752941176470588 0.752941176470588 1" />
      </material>
    </visual>
    <collision>
      <origin
        xyz="0 0 0"
        rpy="0 0 0" />
      <geometry>
        <mesh
          filename="package://4090_3.0_12_6/meshes/RB_THIGH.STL" />
      </geometry>
    </collision>
  </link>
  <joint
    name="RB_HFE"
    type="revolute">
    <origin
      xyz="-0.09 0.0945 0.1537"
      rpy="-1.5708 0 0" />
    <parent
      link="RB_HIP" />
    <child
      link="RB_THIGH" />
    <axis
      xyz="0 0 1" />
    <limit
      lower="0"
      upper="0"
      effort="0"
      velocity="0" />
  </joint>
  <link
    name="RB_SHANK">
    <inertial>
      <origin
        xyz="-0.00125500608314014 -0.107331782247017 -0.0111172003220849"
        rpy="0 0 0" />
      <mass
        value="0.577673514828141" />
      <inertia
        ixx="0.00449645483046401"
        ixy="-4.91078712883112E-05"
        ixz="-4.437953249703E-08"
        iyy="6.70048835728804E-05"
        iyz="-2.41738131906603E-06"
        izz="0.00452066750610663" />
    </inertial>
    <visual>
      <origin
        xyz="0 0 0"
        rpy="0 0 0" />
      <geometry>
        <mesh
          filename="package://4090_3.0_12_6/meshes/RB_SHANK.STL" />
      </geometry>
      <material
        name="">
        <color
          rgba="0.752941176470588 0.752941176470588 0.752941176470588 1" />
      </material>
    </visual>
    <collision>
      <origin
        xyz="0 0 0"
        rpy="0 0 0" />
      <geometry>
        <mesh
          filename="package://4090_3.0_12_6/meshes/RB_SHANK.STL" />
      </geometry>
    </collision>
  </link>
  <joint
    name="RB_KFE"
    type="revolute">
    <origin
      xyz="-0.1782 0.090798 -0.0835"
      rpy="0 0 0" />
    <parent
      link="RB_THIGH" />
    <child
      link="RB_SHANK" />
    <axis
      xyz="0 0 1" />
    <limit
      lower="0"
      upper="0"
      effort="0"
      velocity="0" />
  </joint>
  <link
    name="RB_FOOT">
    <inertial>
      <origin
        xyz="-0.002716580999995 0.0188315867457448 -0.00025044884478248"
        rpy="0 0 0" />
      <mass
        value="0.0652348538555784" />
      <inertia
        ixx="1.2151281102867E-05"
        ixy="8.45710400772865E-08"
        ixz="3.01755082389859E-08"
        iyy="1.32055889001146E-05"
        iyz="9.48720653283993E-08"
        izz="1.43072574928687E-05" />
    </inertial>
    <visual>
      <origin
        xyz="0 0 0"
        rpy="0 0 0" />
      <geometry>
        <mesh
          filename="package://4090_3.0_12_6/meshes/RB_FOOT.STL" />
      </geometry>
      <material
        name="">
        <color
          rgba="0.501960784313725 0.501960784313725 0.752941176470588 1" />
      </material>
    </visual>
    <collision>
      <origin
        xyz="0 0 0"
        rpy="0 0 0" />
      <geometry>
        <mesh
          filename="package://4090_3.0_12_6/meshes/RB_FOOT.STL" />
      </geometry>
    </collision>
  </link>
  <joint
    name="RB_FIX"
    type="fixed">
    <origin
      xyz="0.0012754 -0.29928 -0.010893"
      rpy="0 0 0" />
    <parent
      link="RB_SHANK" />
    <child
      link="RB_FOOT" />
    <axis
      xyz="0 0 0" />
  </joint>
  <link
    name="LF_HIP">
    <inertial>
      <origin
        xyz="-0.02841 -0.0013383 -0.10482"
        rpy="0 0 0" />
      <mass
        value="1.1161" />
      <inertia
        ixx="0.0013596"
        ixy="-3.0608E-05"
        ixz="-0.00022242"
        iyy="0.0021096"
        iyz="-1.3892E-05"
        izz="0.0016645" />
    </inertial>
    <visual>
      <origin
        xyz="0 0 0"
        rpy="0 0 0" />
      <geometry>
        <mesh
          filename="package://4090_3.0_12_6/meshes/LF_HIP.STL" />
      </geometry>
      <material
        name="">
        <color
          rgba="0.75294 0.75294 0.75294 1" />
      </material>
    </visual>
    <collision>
      <origin
        xyz="0 0 0"
        rpy="0 0 0" />
      <geometry>
        <mesh
          filename="package://4090_3.0_12_6/meshes/LF_HIP.STL" />
      </geometry>
    </collision>
  </link>
  <joint
    name="LF_HAA"
    type="revolute">
    <origin
      xyz="0.3 -0.45 0.0895"
      rpy="0 0 3.1416" />
    <parent
      link="BASE" />
    <child
      link="LF_HIP" />
    <axis
      xyz="0 0 1" />
    <limit
      lower="0"
      upper="0"
      effort="0"
      velocity="0" />
  </joint>
  <link
    name="LF_THIGH">
    <inertial>
      <origin
        xyz="-0.0284793864088504 0.0124922847130274 0.080989191133168"
        rpy="0 0 0" />
      <mass
        value="1.00124208339402" />
      <inertia
        ixx="0.001047772429436"
        ixy="0.000929231483296638"
        ixz="-2.63860235389285E-05"
        iyy="0.00212933816261843"
        iyz="1.15741891396455E-05"
        izz="0.00281211985283666" />
    </inertial>
    <visual>
      <origin
        xyz="0 0 0"
        rpy="0 0 0" />
      <geometry>
        <mesh
          filename="package://4090_3.0_12_6/meshes/LF_THIGH.STL" />
      </geometry>
      <material
        name="">
        <color
          rgba="0.752941176470588 0.752941176470588 0.752941176470588 1" />
      </material>
    </visual>
    <collision>
      <origin
        xyz="0 0 0"
        rpy="0 0 0" />
      <geometry>
        <mesh
          filename="package://4090_3.0_12_6/meshes/LF_THIGH.STL" />
      </geometry>
    </collision>
  </link>
  <joint
    name="LF_HFE"
    type="revolute">
    <origin
      xyz="-0.09 0.0795 -0.154"
      rpy="1.5708 0 0" />
    <parent
      link="LF_HIP" />
    <child
      link="LF_THIGH" />
    <axis
      xyz="0 0 1" />
    <limit
      lower="0"
      upper="0"
      effort="0"
      velocity="0" />
  </joint>
  <link
    name="LF_SHANK">
    <inertial>
      <origin
        xyz="-0.00125500608314022 -0.107331782247018 0.0108827996779152"
        rpy="0 0 0" />
      <mass
        value="0.577673514828143" />
      <inertia
        ixx="0.00449645483046403"
        ixy="-4.91078712883109E-05"
        ixz="-4.43795324971029E-08"
        iyy="6.70048835728809E-05"
        iyz="-2.41738131906594E-06"
        izz="0.00452066750610664" />
    </inertial>
    <visual>
      <origin
        xyz="0 0 0"
        rpy="0 0 0" />
      <geometry>
        <mesh
          filename="package://4090_3.0_12_6/meshes/LF_SHANK.STL" />
      </geometry>
      <material
        name="">
        <color
          rgba="0.752941176470588 0.752941176470588 0.752941176470588 1" />
      </material>
    </visual>
    <collision>
      <origin
        xyz="0 0 0"
        rpy="0 0 0" />
      <geometry>
        <mesh
          filename="package://4090_3.0_12_6/meshes/LF_SHANK.STL" />
      </geometry>
    </collision>
  </link>
  <joint
    name="LF_KFE"
    type="revolute">
    <origin
      xyz="-0.1782 0.090798 0.0685"
      rpy="0 0 0" />
    <parent
      link="LF_THIGH" />
    <child
      link="LF_SHANK" />
    <axis
      xyz="0 0 1" />
    <limit
      lower="0"
      upper="0"
      effort="0"
      velocity="0" />
  </joint>
  <link
    name="LF_FOOT">
    <inertial>
      <origin
        xyz="0.00271656736681947 0.0188315943234567 0.00025042343045889"
        rpy="0 0 0" />
      <mass
        value="0.0652349946450809" />
      <inertia
        ixx="1.21513086039564E-05"
        ixy="-8.45642904110766E-08"
        ixz="3.01642816343798E-08"
        iyy="1.32056141029123E-05"
        iyz="-9.48605110233173E-08"
        izz="1.43072682919343E-05" />
    </inertial>
    <visual>
      <origin
        xyz="0 0 0"
        rpy="0 0 0" />
      <geometry>
        <mesh
          filename="package://4090_3.0_12_6/meshes/LF_FOOT.STL" />
      </geometry>
      <material
        name="">
        <color
          rgba="0.501960784313725 0.501960784313725 0.752941176470588 1" />
      </material>
    </visual>
    <collision>
      <origin
        xyz="0 0 0"
        rpy="0 0 0" />
      <geometry>
        <mesh
          filename="package://4090_3.0_12_6/meshes/LF_FOOT.STL" />
      </geometry>
    </collision>
  </link>
  <joint
    name="LF_FIX"
    type="fixed">
    <origin
      xyz="0.0012754 -0.29928 0.011107"
      rpy="3.1416 0 3.1416" />
    <parent
      link="LF_SHANK" />
    <child
      link="LF_FOOT" />
    <axis
      xyz="0 0 0" />
  </joint>
  <link
    name="LM_HIP">
    <inertial>
      <origin
        xyz="-0.02841 -0.0013383 -0.10482"
        rpy="0 0 0" />
      <mass
        value="1.1161" />
      <inertia
        ixx="0.0013596"
        ixy="-3.0609E-05"
        ixz="-0.00022242"
        iyy="0.0021096"
        iyz="-1.3892E-05"
        izz="0.0016645" />
    </inertial>
    <visual>
      <origin
        xyz="0 0 0"
        rpy="0 0 0" />
      <geometry>
        <mesh
          filename="package://4090_3.0_12_6/meshes/LM_HIP.STL" />
      </geometry>
      <material
        name="">
        <color
          rgba="0.75294 0.75294 0.75294 1" />
      </material>
    </visual>
    <collision>
      <origin
        xyz="0 0 0"
        rpy="0 0 0" />
      <geometry>
        <mesh
          filename="package://4090_3.0_12_6/meshes/LM_HIP.STL" />
      </geometry>
    </collision>
  </link>
  <joint
    name="LM_HAA"
    type="revolute">
    <origin
      xyz="0.4 0 0.0895"
      rpy="0 0 3.1416" />
    <parent
      link="BASE" />
    <child
      link="LM_HIP" />
    <axis
      xyz="0 0 1" />
    <limit
      lower="0"
      upper="0"
      effort="0"
      velocity="0" />
  </joint>
  <link
    name="LM_THIGH">
    <inertial>
      <origin
        xyz="-0.028479 0.012492 0.080989"
        rpy="0 0 0" />
      <mass
        value="1.0012" />
      <inertia
        ixx="0.0010478"
        ixy="0.00092923"
        ixz="-2.6386E-05"
        iyy="0.0021293"
        iyz="1.1574E-05"
        izz="0.0028121" />
    </inertial>
    <visual>
      <origin
        xyz="0 0 0"
        rpy="0 0 0" />
      <geometry>
        <mesh
          filename="package://4090_3.0_12_6/meshes/LM_THIGH.STL" />
      </geometry>
      <material
        name="">
        <color
          rgba="0.75294 0.75294 0.75294 1" />
      </material>
    </visual>
    <collision>
      <origin
        xyz="0 0 0"
        rpy="0 0 0" />
      <geometry>
        <mesh
          filename="package://4090_3.0_12_6/meshes/LM_THIGH.STL" />
      </geometry>
    </collision>
  </link>
  <joint
    name="LM_HFE"
    type="revolute">
    <origin
      xyz="-0.09 0.0795 -0.154"
      rpy="1.5708 0 0" />
    <parent
      link="LM_HIP" />
    <child
      link="LM_THIGH" />
    <axis
      xyz="0 0 1" />
    <limit
      lower="0"
      upper="0"
      effort="0"
      velocity="0" />
  </joint>
  <link
    name="LM_SHANK">
    <inertial>
      <origin
        xyz="-0.00125500608314022 -0.107331782247017 0.0108827996779152"
        rpy="0 0 0" />
      <mass
        value="0.577673514828143" />
      <inertia
        ixx="0.00449645483046402"
        ixy="-4.91078712883103E-05"
        ixz="-4.43795324970595E-08"
        iyy="6.70048835728807E-05"
        iyz="-2.41738131906586E-06"
        izz="0.00452066750610664" />
    </inertial>
    <visual>
      <origin
        xyz="0 0 0"
        rpy="0 0 0" />
      <geometry>
        <mesh
          filename="package://4090_3.0_12_6/meshes/LM_SHANK.STL" />
      </geometry>
      <material
        name="">
        <color
          rgba="0.752941176470588 0.752941176470588 0.752941176470588 1" />
      </material>
    </visual>
    <collision>
      <origin
        xyz="0 0 0"
        rpy="0 0 0" />
      <geometry>
        <mesh
          filename="package://4090_3.0_12_6/meshes/LM_SHANK.STL" />
      </geometry>
    </collision>
  </link>
  <joint
    name="LM_KFE"
    type="revolute">
    <origin
      xyz="-0.1782 0.090798 0.0685"
      rpy="0 0 0" />
    <parent
      link="LM_THIGH" />
    <child
      link="LM_SHANK" />
    <axis
      xyz="0 0 1" />
    <limit
      lower="0"
      upper="0"
      effort="0"
      velocity="0" />
  </joint>
  <link
    name="LM_FOOT">
    <inertial>
      <origin
        xyz="0.00271656361742068 0.0188316008407416 0.000250408389803665"
        rpy="0 0 0" />
      <mass
        value="0.0652350820492717" />
      <inertia
        ixx="1.21513263610223E-05"
        ixy="-8.45621976063382E-08"
        ixz="3.01624078329654E-08"
        iyy="1.32056265753874E-05"
        iyz="-9.48519249318527E-08"
        izz="1.43072753201107E-05" />
    </inertial>
    <visual>
      <origin
        xyz="0 0 0"
        rpy="0 0 0" />
      <geometry>
        <mesh
          filename="package://4090_3.0_12_6/meshes/LM_FOOT.STL" />
      </geometry>
      <material
        name="">
        <color
          rgba="0.501960784313725 0.501960784313725 0.752941176470588 1" />
      </material>
    </visual>
    <collision>
      <origin
        xyz="0 0 0"
        rpy="0 0 0" />
      <geometry>
        <mesh
          filename="package://4090_3.0_12_6/meshes/LM_FOOT.STL" />
      </geometry>
    </collision>
  </link>
  <joint
    name="LM_FIX"
    type="fixed">
    <origin
      xyz="0.0012754 -0.29928 0.011107"
      rpy="3.1416 0 3.1416" />
    <parent
      link="LM_SHANK" />
    <child
      link="LM_FOOT" />
    <axis
      xyz="0 0 0" />
  </joint>
  <link
    name="LB_HIP">
    <inertial>
      <origin
        xyz="-0.02841 0.0013388 -0.10452"
        rpy="0 0 0" />
      <mass
        value="1.1161" />
      <inertia
        ixx="0.0013596"
        ixy="3.0609E-05"
        ixz="-0.00022242"
        iyy="0.0021096"
        iyz="-1.3892E-05"
        izz="0.0016645" />
    </inertial>
    <visual>
      <origin
        xyz="0 0 0"
        rpy="0 0 0" />
      <geometry>
        <mesh
          filename="package://4090_3.0_12_6/meshes/LB_HIP.STL" />
      </geometry>
      <material
        name="">
        <color
          rgba="0.75294 0.75294 0.75294 1" />
      </material>
    </visual>
    <collision>
      <origin
        xyz="0 0 0"
        rpy="0 0 0" />
      <geometry>
        <mesh
          filename="package://4090_3.0_12_6/meshes/LB_HIP.STL" />
      </geometry>
    </collision>
  </link>
  <joint
    name="LB_HAA"
    type="revolute">
    <origin
      xyz="0.3 0.45 0.0895"
      rpy="0 0 3.1416" />
    <parent
      link="BASE" />
    <child
      link="LB_HIP" />
    <axis
      xyz="0 0 1" />
    <limit
      lower="0"
      upper="0"
      effort="0"
      velocity="0" />
  </joint>
  <link
    name="LB_THIGH">
    <inertial>
      <origin
        xyz="-0.028479 0.012492 0.093011"
        rpy="0 0 0" />
      <mass
        value="1.0012" />
      <inertia
        ixx="0.0010478"
        ixy="0.00092923"
        ixz="2.6386E-05"
        iyy="0.0021293"
        iyz="-1.1574E-05"
        izz="0.0028121" />
    </inertial>
    <visual>
      <origin
        xyz="0 0 0"
        rpy="0 0 0" />
      <geometry>
        <mesh
          filename="package://4090_3.0_12_6/meshes/LB_THIGH.STL" />
      </geometry>
      <material
        name="">
        <color
          rgba="0.75294 0.75294 0.75294 1" />
      </material>
    </visual>
    <collision>
      <origin
        xyz="0 0 0"
        rpy="0 0 0" />
      <geometry>
        <mesh
          filename="package://4090_3.0_12_6/meshes/LB_THIGH.STL" />
      </geometry>
    </collision>
  </link>
  <joint
    name="LB_HFE"
    type="revolute">
    <origin
      xyz="-0.09 0.0945 -0.154"
      rpy="1.5708 0 0" />
    <parent
      link="LB_HIP" />
    <child
      link="LB_THIGH" />
    <axis
      xyz="0 0 1" />
    <limit
      lower="0"
      upper="0"
      effort="0"
      velocity="0" />
  </joint>
  <link
    name="LB_SHANK">
    <inertial>
      <origin
        xyz="-0.0012227 -0.10733 0.011117"
        rpy="0 0 0" />
      <mass
        value="0.57767" />
      <inertia
        ixx="0.0044964"
        ixy="-5.3153E-05"
        ixz="1.1428E-08"
        iyy="6.7098E-05"
        iyz="2.4178E-06"
        izz="0.0045207" />
    </inertial>
    <visual>
      <origin
        xyz="0 0 0"
        rpy="0 0 0" />
      <geometry>
        <mesh
          filename="package://4090_3.0_12_6/meshes/LB_SHANK.STL" />
      </geometry>
      <material
        name="">
        <color
          rgba="0.75294 0.75294 0.75294 1" />
      </material>
    </visual>
    <collision>
      <origin
        xyz="0 0 0"
        rpy="0 0 0" />
      <geometry>
        <mesh
          filename="package://4090_3.0_12_6/meshes/LB_SHANK.STL" />
      </geometry>
    </collision>
  </link>
  <joint
    name="LB_KFE"
    type="revolute">
    <origin
      xyz="-0.1782 0.090798 0.0835"
      rpy="0 0 0" />
    <parent
      link="LB_THIGH" />
    <child
      link="LB_SHANK" />
    <axis
      xyz="0 0 1" />
    <limit
      lower="0"
      upper="0"
      effort="0"
      velocity="0" />
  </joint>
  <link
    name="LB_FOOT">
    <inertial>
      <origin
        xyz="-0.0031505 0.018764 -0.00025041"
        rpy="0 0 0" />
      <mass
        value="0.065235" />
      <inertia
        ixx="1.2148E-05"
        ixy="6.015E-08"
        ixz="2.7952E-08"
        iyy="1.3209E-05"
        iyz="9.5546E-08"
        izz="1.4307E-05" />
    </inertial>
    <visual>
      <origin
        xyz="0 0 0"
        rpy="0 0 0" />
      <geometry>
        <mesh
          filename="package://4090_3.0_12_6/meshes/LB_FOOT.STL" />
      </geometry>
      <material
        name="">
        <color
          rgba="0.50196 0.50196 0.75294 1" />
      </material>
    </visual>
    <collision>
      <origin
        xyz="0 0 0"
        rpy="0 0 0" />
      <geometry>
        <mesh
          filename="package://4090_3.0_12_6/meshes/LB_FOOT.STL" />
      </geometry>
    </collision>
  </link>
  <joint
    name="LB_FIX"
    type="fixed">
    <origin
      xyz="-0.0081826 -0.29917 0.010893"
      rpy="3.1416 0 3.1416" />
    <parent
      link="LB_SHANK" />
    <child
      link="LB_FOOT" />
    <axis
      xyz="0 0 0" />
  </joint>
</robot>