<?xml version="1.0" encoding="utf-8"?>
<!-- This URDF was automatically created by SolidWorks to URDF Exporter! Originally created by Stephen Brawner (brawner@gmail.com) 
     Commit Version: 1.6.0-4-g7f85cfe  Build Version: 1.6.7995.38578
     For more information, please see http://wiki.ros.org/sw_urdf_exporter -->
<robot
  name="4090_3.0_2.SLDASM">
  <link
    name="BASE">
    <inertial>
      <origin
        xyz="-8.7698E-07 -0.0001155 -0.14728"
        rpy="0 0 0" />
      <mass
        value="7.4416" />
      <inertia
        ixx="0.10225"
        ixy="1.3878E-07"
        ixz="-3.4668E-08"
        iyy="0.55067"
        iyz="-8.473E-06"
        izz="0.64267" />
    </inertial>
    <visual>
      <origin
        xyz="0 0 0"
        rpy="0 0 0" />
      <geometry>
        <mesh
          filename="package://4090_3.0_2.SLDASM/meshes/BASE.STL" />
      </geometry>
      <material
        name="">
        <color
          rgba="0.88627 0.81961 0.65882 1" />
      </material>
    </visual>
    <collision>
      <origin
        xyz="0 0 0"
        rpy="0 0 0" />
      <geometry>
        <mesh
          filename="package://4090_3.0_2.SLDASM/meshes/BASE.STL" />
      </geometry>
    </collision>
  </link>
  <link
    name="RF_HIP">
    <inertial>
      <origin
        xyz="-0.00069579 -0.027572 -0.10482"
        rpy="0 0 0" />
      <mass
        value="1.1161" />
      <inertia
        ixx="0.0021096"
        ixy="-3.06E-05"
        ixz="-1.3892E-05"
        iyy="0.0013596"
        iyz="-0.00022242"
        izz="0.0016645" />
    </inertial>
    <visual>
      <origin
        xyz="0 0 0"
        rpy="0 0 0" />
      <geometry>
        <mesh
          filename="package://4090_3.0_2.SLDASM/meshes/RF_HIP.STL" />
      </geometry>
      <material
        name="">
        <color
          rgba="0.75294 0.75294 0.75294 1" />
      </material>
    </visual>
    <collision>
      <origin
        xyz="0 0 0"
        rpy="0 0 0" />
      <geometry>
        <mesh
          filename="package://4090_3.0_2.SLDASM/meshes/RF_HIP.STL" />
      </geometry>
    </collision>
  </link>
  <joint
    name="RF_HAA"
    type="revolute">
    <origin
      xyz="0.44916 -0.099354 -0.1105"
      rpy="0 0 -1.5708" />
    <parent
      link="BASE" />
    <child
      link="RF_HIP" />
    <axis
      xyz="0 0 1" />
    <limit
      lower="-1"
      upper="1"
      effort="80"
      velocity="15.8" />
  </joint>
  <link
    name="RF_THIGH">
    <inertial>
      <origin
        xyz="-0.029871 -0.020257 -0.080989"
        rpy="0 0 0" />
      <mass
        value="1.0012" />
      <inertia
        ixx="0.0011206"
        ixy="-0.00096795"
        ixz="2.2607E-05"
        iyy="0.0020565"
        iyz="1.7864E-05"
        izz="0.0028121" />
    </inertial>
    <visual>
      <origin
        xyz="0 0 0"
        rpy="0 0 0" />
      <geometry>
        <mesh
          filename="package://4090_3.0_2.SLDASM/meshes/RF_THIGH.STL" />
      </geometry>
      <material
        name="">
        <color
          rgba="0.75294 0.75294 0.75294 1" />
      </material>
    </visual>
    <collision>
      <origin
        xyz="0 0 0"
        rpy="0 0 0" />
      <geometry>
        <mesh
          filename="package://4090_3.0_2.SLDASM/meshes/RF_THIGH.STL" />
      </geometry>
    </collision>
  </link>
  <joint
    name="RF_HFE"
    type="revolute">
    <origin
      xyz="0.080143 -0.083692 -0.15302"
      rpy="1.5708 0 1.5708" />
    <parent
      link="RF_HIP" />
    <child
      link="RF_THIGH" />
    <axis
      xyz="0 0 1" />
    <limit
      lower="-1"
      upper="1"
      effort="80"
      velocity="15.8" />
  </joint>
  <link
    name="RF_SHANK">
    <inertial>
      <origin
        xyz="0.055841 -0.091671 -0.010883"
        rpy="0 0 0" />
      <mass
        value="0.57767" />
      <inertia
        ixx="0.0033003"
        ixy="0.0019672"
        ixz="-1.2715E-06"
        iyy="0.0012631"
        iyz="2.0564E-06"
        izz="0.0045207" />
    </inertial>
    <visual>
      <origin
        xyz="0 0 0"
        rpy="0 0 0" />
      <geometry>
        <mesh
          filename="package://4090_3.0_2.SLDASM/meshes/RF_SHANK.STL" />
      </geometry>
      <material
        name="">
        <color
          rgba="0.75294 0.75294 0.75294 1" />
      </material>
    </visual>
    <collision>
      <origin
        xyz="0 0 0"
        rpy="0 0 0" />
      <geometry>
        <mesh
          filename="package://4090_3.0_2.SLDASM/meshes/RF_SHANK.STL" />
      </geometry>
    </collision>
  </link>
  <joint
    name="RF_KFE"
    type="revolute">
    <origin
      xyz="-0.1693 -0.11569 -0.0685"
      rpy="0 0 0" />
    <parent
      link="RF_THIGH" />
    <child
      link="RF_SHANK" />
    <axis
      xyz="0 0 1" />
    <limit
      lower="-1"
      upper="1"
      effort="80"
      velocity="15.8" />
  </joint>
  <link
    name="RF_FOOT">
    <inertial>
      <origin
        xyz="-0.00024987 -0.0072718 -0.017582"
        rpy="0 0 0" />
      <mass
        value="0.065235" />
      <inertia
        ixx="1.4307E-05"
        ixy="-7.3984E-08"
        ixz="-6.646E-08"
        iyy="1.25E-05"
        iyz="5.0324E-07"
        izz="1.2857E-05" />
    </inertial>
    <visual>
      <origin
        xyz="0 0 0"
        rpy="0 0 0" />
      <geometry>
        <mesh
          filename="package://4090_3.0_2.SLDASM/meshes/RF_FOOT.STL" />
      </geometry>
      <material
        name="">
        <color
          rgba="0.50196 0.50196 0.75294 1" />
      </material>
    </visual>
    <collision>
      <origin
        xyz="0 0 0"
        rpy="0 0 0" />
      <geometry>
        <mesh
          filename="package://4090_3.0_2.SLDASM/meshes/RF_FOOT.STL" />
      </geometry>
    </collision>
  </link>
  <joint
    name="RF_FIX"
    type="fixed">
    <origin
      xyz="0.15159 -0.25804 -0.011107"
      rpy="1.5708 1.5708 0" />
    <parent
      link="RF_SHANK" />
    <child
      link="RF_FOOT" />
    <axis
      xyz="0 0 0" />
  </joint>
  <link
    name="RM_HIP">
    <inertial>
      <origin
        xyz="0.0023852 -0.028272 -0.10482"
        rpy="0 0 0" />
      <mass
        value="1.1161" />
      <inertia
        ixx="0.0021096"
        ixy="3.0591E-05"
        ixz="1.3892E-05"
        iyy="0.0013596"
        iyz="-0.00022242"
        izz="0.0016645" />
    </inertial>
    <visual>
      <origin
        xyz="0 0 0"
        rpy="0 0 0" />
      <geometry>
        <mesh
          filename="package://4090_3.0_2.SLDASM/meshes/RM_HIP.STL" />
      </geometry>
      <material
        name="">
        <color
          rgba="0.75294 0.75294 0.75294 1" />
      </material>
    </visual>
    <collision>
      <origin
        xyz="0 0 0"
        rpy="0 0 0" />
      <geometry>
        <mesh
          filename="package://4090_3.0_2.SLDASM/meshes/RM_HIP.STL" />
      </geometry>
    </collision>
  </link>
  <joint
    name="RM_HAA"
    type="revolute">
    <origin
      xyz="-0.00013893 -0.19895 -0.1105"
      rpy="0 0 -1.5708" />
    <parent
      link="BASE" />
    <child
      link="RM_HIP" />
    <axis
      xyz="0 0 1" />
    <limit
      lower="-1"
      upper="1"
      effort="80"
      velocity="15.8" />
  </joint>
  <link
    name="RM_THIGH">
    <inertial>
      <origin
        xyz="-0.024916 -0.019464 -0.093011"
        rpy="0 0 0" />
      <mass
        value="1.0012" />
      <inertia
        ixx="0.0010542"
        ixy="-0.00093295"
        ixz="-2.3217E-05"
        iyy="0.0021229"
        iyz="-1.7064E-05"
        izz="0.0028121" />
    </inertial>
    <visual>
      <origin
        xyz="0 0 0"
        rpy="0 0 0" />
      <geometry>
        <mesh
          filename="package://4090_3.0_2.SLDASM/meshes/RM_THIGH.STL" />
      </geometry>
      <material
        name="">
        <color
          rgba="0.75294 0.75294 0.75294 1" />
      </material>
    </visual>
    <collision>
      <origin
        xyz="0 0 0"
        rpy="0 0 0" />
      <geometry>
        <mesh
          filename="package://4090_3.0_2.SLDASM/meshes/RM_THIGH.STL" />
      </geometry>
    </collision>
  </link>
  <joint
    name="RM_HFE"
    type="revolute">
    <origin
      xyz="0.095547 -0.090004 -0.15295"
      rpy="1.5708 0 1.5708" />
    <parent
      link="RM_HIP" />
    <child
      link="RM_THIGH" />
    <axis
      xyz="0 0 1" />
    <limit
      lower="-1"
      upper="1"
      effort="80"
      velocity="15.8" />
  </joint>
  <link
    name="RM_SHANK">
    <inertial>
      <origin
        xyz="0.052579 -0.09358 -0.011117"
        rpy="0 0 0" />
      <mass
        value="0.57767" />
      <inertia
        ixx="0.0034316"
        ixy="0.0018935"
        ixz="1.1703E-06"
        iyy="0.0011318"
        iyz="-2.1157E-06"
        izz="0.0045207" />
    </inertial>
    <visual>
      <origin
        xyz="0 0 0"
        rpy="0 0 0" />
      <geometry>
        <mesh
          filename="package://4090_3.0_2.SLDASM/meshes/RM_SHANK.STL" />
      </geometry>
      <material
        name="">
        <color
          rgba="0.75294 0.75294 0.75294 1" />
      </material>
    </visual>
    <collision>
      <origin
        xyz="0 0 0"
        rpy="0 0 0" />
      <geometry>
        <mesh
          filename="package://4090_3.0_2.SLDASM/meshes/RM_SHANK.STL" />
      </geometry>
    </collision>
  </link>
  <joint
    name="RM_KFE"
    type="revolute">
    <origin
      xyz="-0.16759 -0.10997 -0.0835"
      rpy="0 0 0" />
    <parent
      link="RM_THIGH" />
    <child
      link="RM_SHANK" />
    <axis
      xyz="0 0 1" />
    <limit
      lower="-1"
      upper="1"
      effort="80"
      velocity="15.8" />
  </joint>
  <link
    name="RM_FOOT">
    <inertial>
      <origin
        xyz="0.00025008 -0.011768 -0.014951"
        rpy="0 0 0" />
      <mass
        value="0.065237" />
      <inertia
        ixx="1.4307E-05"
        ixy="2.1816E-08"
        ixz="9.7324E-08"
        iyy="1.2342E-05"
        iyz="4.1449E-07"
        izz="1.3015E-05" />
    </inertial>
    <visual>
      <origin
        xyz="0 0 0"
        rpy="0 0 0" />
      <geometry>
        <mesh
          filename="package://4090_3.0_2.SLDASM/meshes/RM_FOOT.STL" />
      </geometry>
      <material
        name="">
        <color
          rgba="0.50196 0.50196 0.75294 1" />
      </material>
    </visual>
    <collision>
      <origin
        xyz="0 0 0"
        rpy="0 0 0" />
      <geometry>
        <mesh
          filename="package://4090_3.0_2.SLDASM/meshes/RM_FOOT.STL" />
      </geometry>
    </collision>
  </link>
  <joint
    name="RM_FIX"
    type="fixed">
    <origin
      xyz="0.15074 -0.25854 -0.010893"
      rpy="1.5708 1.5708 0" />
    <parent
      link="RM_SHANK" />
    <child
      link="RM_FOOT" />
    <axis
      xyz="0 0 0" />
  </joint>
  <link
    name="RB_HIP">
    <inertial>
      <origin
        xyz="0.0023139 -0.028006 -0.10482"
        rpy="0 0 0" />
      <mass
        value="1.1161" />
      <inertia
        ixx="0.0021096"
        ixy="3.0592E-05"
        ixz="1.3892E-05"
        iyy="0.0013596"
        iyz="-0.00022242"
        izz="0.0016645" />
    </inertial>
    <visual>
      <origin
        xyz="0 0 0"
        rpy="0 0 0" />
      <geometry>
        <mesh
          filename="package://4090_3.0_2.SLDASM/meshes/RB_HIP.STL" />
      </geometry>
      <material
        name="">
        <color
          rgba="0.75294 0.75294 0.75294 1" />
      </material>
    </visual>
    <collision>
      <origin
        xyz="0 0 0"
        rpy="0 0 0" />
      <geometry>
        <mesh
          filename="package://4090_3.0_2.SLDASM/meshes/RB_HIP.STL" />
      </geometry>
    </collision>
  </link>
  <joint
    name="RB_HAA"
    type="revolute">
    <origin
      xyz="-0.45041 -0.099022 -0.1105"
      rpy="0 0 -1.5708" />
    <parent
      link="BASE" />
    <child
      link="RB_HIP" />
    <axis
      xyz="0 0 1" />
    <limit
      lower="-1"
      upper="1"
      effort="80"
      velocity="15.8" />
  </joint>
  <link
    name="RB_THIGH">
    <inertial>
      <origin
        xyz="-0.024916 -0.019464 -0.093011"
        rpy="0 0 0" />
      <mass
        value="1.0012" />
      <inertia
        ixx="0.0010542"
        ixy="-0.00093295"
        ixz="-2.3217E-05"
        iyy="0.0021229"
        iyz="-1.7064E-05"
        izz="0.0028121" />
    </inertial>
    <visual>
      <origin
        xyz="0 0 0"
        rpy="0 0 0" />
      <geometry>
        <mesh
          filename="package://4090_3.0_2.SLDASM/meshes/RB_THIGH.STL" />
      </geometry>
      <material
        name="">
        <color
          rgba="0.75294 0.75294 0.75294 1" />
      </material>
    </visual>
    <collision>
      <origin
        xyz="0 0 0"
        rpy="0 0 0" />
      <geometry>
        <mesh
          filename="package://4090_3.0_2.SLDASM/meshes/RB_THIGH.STL" />
      </geometry>
    </collision>
  </link>
  <joint
    name="RB_HFE"
    type="revolute">
    <origin
      xyz="0.095476 -0.089738 -0.15295"
      rpy="1.5708 0 1.5708" />
    <parent
      link="RB_HIP" />
    <child
      link="RB_THIGH" />
    <axis
      xyz="0 0 1" />
    <limit
      lower="-1"
      upper="1"
      effort="80"
      velocity="15.8" />
  </joint>
  <link
    name="RB_SHANK">
    <inertial>
      <origin
        xyz="0.052579 -0.09358 -0.011117"
        rpy="0 0 0" />
      <mass
        value="0.57767" />
      <inertia
        ixx="0.0034316"
        ixy="0.0018935"
        ixz="1.1703E-06"
        iyy="0.0011318"
        iyz="-2.1157E-06"
        izz="0.0045207" />
    </inertial>
    <visual>
      <origin
        xyz="0 0 0"
        rpy="0 0 0" />
      <geometry>
        <mesh
          filename="package://4090_3.0_2.SLDASM/meshes/RB_SHANK.STL" />
      </geometry>
      <material
        name="">
        <color
          rgba="0.75294 0.75294 0.75294 1" />
      </material>
    </visual>
    <collision>
      <origin
        xyz="0 0 0"
        rpy="0 0 0" />
      <geometry>
        <mesh
          filename="package://4090_3.0_2.SLDASM/meshes/RB_SHANK.STL" />
      </geometry>
    </collision>
  </link>
  <joint
    name="RB_KFE"
    type="revolute">
    <origin
      xyz="-0.16759 -0.10997 -0.0835"
      rpy="0 0 0" />
    <parent
      link="RB_THIGH" />
    <child
      link="RB_SHANK" />
    <axis
      xyz="0 0 1" />
    <limit
      lower="-1"
      upper="1"
      effort="80"
      velocity="15.8" />
  </joint>
  <link
    name="RB_FOOT">
    <inertial>
      <origin
        xyz="0.00025012 -0.011768 -0.014951"
        rpy="0 0 0" />
      <mass
        value="0.065237" />
      <inertia
        ixx="1.4307E-05"
        ixy="2.1815E-08"
        ixz="9.7349E-08"
        iyy="1.2342E-05"
        iyz="4.1449E-07"
        izz="1.3015E-05" />
    </inertial>
    <visual>
      <origin
        xyz="0 0 0"
        rpy="0 0 0" />
      <geometry>
        <mesh
          filename="package://4090_3.0_2.SLDASM/meshes/RB_FOOT.STL" />
      </geometry>
      <material
        name="">
        <color
          rgba="0.50196 0.50196 0.75294 1" />
      </material>
    </visual>
    <collision>
      <origin
        xyz="0 0 0"
        rpy="0 0 0" />
      <geometry>
        <mesh
          filename="package://4090_3.0_2.SLDASM/meshes/RB_FOOT.STL" />
      </geometry>
    </collision>
  </link>
  <joint
    name="RB_FIX"
    type="fixed">
    <origin
      xyz="0.15074 -0.25854 -0.010893"
      rpy="1.5708 1.5708 0" />
    <parent
      link="RB_SHANK" />
    <child
      link="RB_FOOT" />
    <axis
      xyz="0 0 0" />
  </joint>
  <link
    name="LF_HIP">
    <inertial>
      <origin
        xyz="-0.0023852 -0.028272 0.10482"
        rpy="0 0 0" />
      <mass
        value="1.1161" />
      <inertia
        ixx="0.0021096"
        ixy="-3.0591E-05"
        ixz="1.3892E-05"
        iyy="0.0013596"
        iyz="0.00022242"
        izz="0.0016645" />
    </inertial>
    <visual>
      <origin
        xyz="0 0 0"
        rpy="0 0 0" />
      <geometry>
        <mesh
          filename="package://4090_3.0_2.SLDASM/meshes/LF_HIP.STL" />
      </geometry>
      <material
        name="">
        <color
          rgba="0.75294 0.75294 0.75294 1" />
      </material>
    </visual>
    <collision>
      <origin
        xyz="0 0 0"
        rpy="0 0 0" />
      <geometry>
        <mesh
          filename="package://4090_3.0_2.SLDASM/meshes/LF_HIP.STL" />
      </geometry>
    </collision>
  </link>
  <joint
    name="LF_HAA"
    type="revolute">
    <origin
      xyz="0.44986 0.10105 -0.1105"
      rpy="3.1416 0 1.5708" />
    <parent
      link="BASE" />
    <child
      link="LF_HIP" />
    <axis
      xyz="0 0 1" />
    <limit
      lower="-1"
      upper="1"
      effort="80"
      velocity="15.8" />
  </joint>
  <link
    name="LF_THIGH">
    <inertial>
      <origin
        xyz="-0.024654 -0.017442 0.080989"
        rpy="0 0 0" />
      <mass
        value="1.0012" />
      <inertia
        ixx="0.0010542"
        ixy="-0.00093295"
        ixz="-2.3217E-05"
        iyy="0.0021229"
        iyz="-1.7064E-05"
        izz="0.0028121" />
    </inertial>
    <visual>
      <origin
        xyz="0 0 0"
        rpy="0 0 0" />
      <geometry>
        <mesh
          filename="package://4090_3.0_2.SLDASM/meshes/LF_THIGH.STL" />
      </geometry>
      <material
        name="">
        <color
          rgba="0.75294 0.75294 0.75294 1" />
      </material>
    </visual>
    <collision>
      <origin
        xyz="0 0 0"
        rpy="0 0 0" />
      <geometry>
        <mesh
          filename="package://4090_3.0_2.SLDASM/meshes/LF_THIGH.STL" />
      </geometry>
    </collision>
  </link>
  <joint
    name="LF_HFE"
    type="revolute">
    <origin
      xyz="0.078453 -0.090266 0.15498"
      rpy="-1.5708 0 1.5708" />
    <parent
      link="LF_HIP" />
    <child
      link="LF_THIGH" />
    <axis
      xyz="0 0 1" />
    <limit
      lower="-1"
      upper="1"
      effort="80"
      velocity="15.8" />
  </joint>
  <link
    name="LF_SHANK">
    <inertial>
      <origin
        xyz="0.052579 -0.09358 0.010883"
        rpy="0 0 0" />
      <mass
        value="0.57767" />
      <inertia
        ixx="0.0034316"
        ixy="0.0018935"
        ixz="1.1703E-06"
        iyy="0.0011318"
        iyz="-2.1157E-06"
        izz="0.0045207" />
    </inertial>
    <visual>
      <origin
        xyz="0 0 0"
        rpy="0 0 0" />
      <geometry>
        <mesh
          filename="package://4090_3.0_2.SLDASM/meshes/LF_SHANK.STL" />
      </geometry>
      <material
        name="">
        <color
          rgba="0.75294 0.75294 0.75294 1" />
      </material>
    </visual>
    <collision>
      <origin
        xyz="0 0 0"
        rpy="0 0 0" />
      <geometry>
        <mesh
          filename="package://4090_3.0_2.SLDASM/meshes/LF_SHANK.STL" />
      </geometry>
    </collision>
  </link>
  <joint
    name="LF_KFE"
    type="revolute">
    <origin
      xyz="-0.16733 -0.10795 0.0685"
      rpy="0 0 0" />
    <parent
      link="LF_THIGH" />
    <child
      link="LF_SHANK" />
    <axis
      xyz="0 0 1" />
    <limit
      lower="-1"
      upper="1"
      effort="80"
      velocity="15.8" />
  </joint>
  <link
    name="LF_FOOT">
    <inertial>
      <origin
        xyz="0.00025012 -0.011768 -0.014951"
        rpy="0 0 0" />
      <mass
        value="0.065237" />
      <inertia
        ixx="1.4307E-05"
        ixy="2.1815E-08"
        ixz="9.7349E-08"
        iyy="1.2342E-05"
        iyz="4.1449E-07"
        izz="1.3015E-05" />
    </inertial>
    <visual>
      <origin
        xyz="0 0 0"
        rpy="0 0 0" />
      <geometry>
        <mesh
          filename="package://4090_3.0_2.SLDASM/meshes/LF_FOOT.STL" />
      </geometry>
      <material
        name="">
        <color
          rgba="0.50196 0.50196 0.75294 1" />
      </material>
    </visual>
    <collision>
      <origin
        xyz="0 0 0"
        rpy="0 0 0" />
      <geometry>
        <mesh
          filename="package://4090_3.0_2.SLDASM/meshes/LF_FOOT.STL" />
      </geometry>
    </collision>
  </link>
  <joint
    name="LF_FIX"
    type="fixed">
    <origin
      xyz="0.15074 -0.25854 0.011107"
      rpy="1.5708 1.5708 0" />
    <parent
      link="LF_SHANK" />
    <child
      link="LF_FOOT" />
    <axis
      xyz="0 0 0" />
  </joint>
  <link
    name="LM_HIP">
    <inertial>
      <origin
        xyz="0.00069766 -0.027571 0.10482"
        rpy="0 0 0" />
      <mass
        value="1.1161" />
      <inertia
        ixx="0.0021096"
        ixy="3.06E-05"
        ixz="-1.3892E-05"
        iyy="0.0013596"
        iyz="0.00022242"
        izz="0.0016645" />
    </inertial>
    <visual>
      <origin
        xyz="0 0 0"
        rpy="0 0 0" />
      <geometry>
        <mesh
          filename="package://4090_3.0_2.SLDASM/meshes/LM_HIP.STL" />
      </geometry>
      <material
        name="">
        <color
          rgba="0.75294 0.75294 0.75294 1" />
      </material>
    </visual>
    <collision>
      <origin
        xyz="0 0 0"
        rpy="0 0 0" />
      <geometry>
        <mesh
          filename="package://4090_3.0_2.SLDASM/meshes/LM_HIP.STL" />
      </geometry>
    </collision>
  </link>
  <joint
    name="LM_HAA"
    type="revolute">
    <origin
      xyz="-0.00084022 0.20064 -0.1105"
      rpy="3.1416 0 1.5708" />
    <parent
      link="BASE" />
    <child
      link="LM_HIP" />
    <axis
      xyz="0 0 1" />
    <limit
      lower="-1"
      upper="1"
      effort="80"
      velocity="15.8" />
  </joint>
  <link
    name="LM_THIGH">
    <inertial>
      <origin
        xyz="-0.023838 -0.020175 0.093011"
        rpy="0 0 0" />
      <mass
        value="1.0012" />
      <inertia
        ixx="0.0011206"
        ixy="-0.00096795"
        ixz="2.2607E-05"
        iyy="0.0020565"
        iyz="1.7864E-05"
        izz="0.0028121" />
    </inertial>
    <visual>
      <origin
        xyz="0 0 0"
        rpy="0 0 0" />
      <geometry>
        <mesh
          filename="package://4090_3.0_2.SLDASM/meshes/LM_THIGH.STL" />
      </geometry>
      <material
        name="">
        <color
          rgba="0.75294 0.75294 0.75294 1" />
      </material>
    </visual>
    <collision>
      <origin
        xyz="0 0 0"
        rpy="0 0 0" />
      <geometry>
        <mesh
          filename="package://4090_3.0_2.SLDASM/meshes/LM_THIGH.STL" />
      </geometry>
    </collision>
  </link>
  <joint
    name="LM_HFE"
    type="revolute">
    <origin
      xyz="0.093859 -0.089724 0.15311"
      rpy="-1.5708 0 1.5708" />
    <parent
      link="LM_HIP" />
    <child
      link="LM_THIGH" />
    <axis
      xyz="0 0 1" />
    <limit
      lower="-1"
      upper="1"
      effort="80"
      velocity="15.8" />
  </joint>
  <link
    name="LM_SHANK">
    <inertial>
      <origin
        xyz="0.055841 -0.091671 0.011117"
        rpy="0 0 0" />
      <mass
        value="0.57767" />
      <inertia
        ixx="0.0033003"
        ixy="0.0019672"
        ixz="-1.2715E-06"
        iyy="0.0012631"
        iyz="2.0564E-06"
        izz="0.0045207" />
    </inertial>
    <visual>
      <origin
        xyz="0 0 0"
        rpy="0 0 0" />
      <geometry>
        <mesh
          filename="package://4090_3.0_2.SLDASM/meshes/LM_SHANK.STL" />
      </geometry>
      <material
        name="">
        <color
          rgba="0.75294 0.75294 0.75294 1" />
      </material>
    </visual>
    <collision>
      <origin
        xyz="0 0 0"
        rpy="0 0 0" />
      <geometry>
        <mesh
          filename="package://4090_3.0_2.SLDASM/meshes/LM_SHANK.STL" />
      </geometry>
    </collision>
  </link>
  <joint
    name="LM_KFE"
    type="revolute">
    <origin
      xyz="-0.16327 -0.11561 0.0835"
      rpy="0 0 0" />
    <parent
      link="LM_THIGH" />
    <child
      link="LM_SHANK" />
    <axis
      xyz="0 0 1" />
    <limit
      lower="-1"
      upper="1"
      effort="80"
      velocity="15.8" />
  </joint>
  <link
    name="LM_FOOT">
    <inertial>
      <origin
        xyz="-0.00024985 -0.0072718 -0.017582"
        rpy="0 0 0" />
      <mass
        value="0.065235" />
      <inertia
        ixx="1.4307E-05"
        ixy="-7.3968E-08"
        ixz="-6.6456E-08"
        iyy="1.25E-05"
        iyz="5.0324E-07"
        izz="1.2857E-05" />
    </inertial>
    <visual>
      <origin
        xyz="0 0 0"
        rpy="0 0 0" />
      <geometry>
        <mesh
          filename="package://4090_3.0_2.SLDASM/meshes/LM_FOOT.STL" />
      </geometry>
      <material
        name="">
        <color
          rgba="0.50196 0.50196 0.75294 1" />
      </material>
    </visual>
    <collision>
      <origin
        xyz="0 0 0"
        rpy="0 0 0" />
      <geometry>
        <mesh
          filename="package://4090_3.0_2.SLDASM/meshes/LM_FOOT.STL" />
      </geometry>
    </collision>
  </link>
  <joint
    name="LM_FIX"
    type="fixed">
    <origin
      xyz="0.15159 -0.25804 0.010893"
      rpy="1.5708 1.5708 0" />
    <parent
      link="LM_SHANK" />
    <child
      link="LM_FOOT" />
    <axis
      xyz="0 0 0" />
  </joint>
  <link
    name="LB_HIP">
    <inertial>
      <origin
        xyz="0.00029197 -0.028272 0.10482"
        rpy="0 0 0" />
      <mass
        value="1.1161" />
      <inertia
        ixx="0.0021096"
        ixy="3.0609E-05"
        ixz="-1.3892E-05"
        iyy="0.0013596"
        iyz="0.00022242"
        izz="0.0016645" />
    </inertial>
    <visual>
      <origin
        xyz="0 0 0"
        rpy="0 0 0" />
      <geometry>
        <mesh
          filename="package://4090_3.0_2.SLDASM/meshes/LB_HIP.STL" />
      </geometry>
      <material
        name="">
        <color
          rgba="0.75294 0.75294 0.75294 1" />
      </material>
    </visual>
    <collision>
      <origin
        xyz="0 0 0"
        rpy="0 0 0" />
      <geometry>
        <mesh
          filename="package://4090_3.0_2.SLDASM/meshes/LB_HIP.STL" />
      </geometry>
    </collision>
  </link>
  <joint
    name="LB_HAA"
    type="revolute">
    <origin
      xyz="-0.45014 0.10105 -0.1105"
      rpy="3.1416 0 1.5708" />
    <parent
      link="BASE" />
    <child
      link="LB_HIP" />
    <axis
      xyz="0 0 1" />
    <limit
      lower="-1"
      upper="1"
      effort="80"
      velocity="15.8" />
  </joint>
  <link
    name="LB_THIGH">
    <inertial>
      <origin
        xyz="-0.023838 -0.020175 0.093011"
        rpy="0 0 0" />
      <mass
        value="1.0012" />
      <inertia
        ixx="0.0011206"
        ixy="-0.00096795"
        ixz="2.2607E-05"
        iyy="0.0020565"
        iyz="1.7864E-05"
        izz="0.0028121" />
    </inertial>
    <visual>
      <origin
        xyz="0 0 0"
        rpy="0 0 0" />
      <geometry>
        <mesh
          filename="package://4090_3.0_2.SLDASM/meshes/LB_THIGH.STL" />
      </geometry>
      <material
        name="">
        <color
          rgba="0.75294 0.75294 0.75294 1" />
      </material>
    </visual>
    <collision>
      <origin
        xyz="0 0 0"
        rpy="0 0 0" />
      <geometry>
        <mesh
          filename="package://4090_3.0_2.SLDASM/meshes/LB_THIGH.STL" />
      </geometry>
    </collision>
  </link>
  <joint
    name="LB_HFE"
    type="revolute">
    <origin
      xyz="0.093453 -0.090425 0.15311"
      rpy="-1.5708 0 1.5708" />
    <parent
      link="LB_HIP" />
    <child
      link="LB_THIGH" />
    <axis
      xyz="0 0 1" />
    <limit
      lower="-1"
      upper="1"
      effort="80"
      velocity="15.8" />
  </joint>
  <link
    name="LB_SHANK">
    <inertial>
      <origin
        xyz="0.055841 -0.091671 0.011117"
        rpy="0 0 0" />
      <mass
        value="0.57767" />
      <inertia
        ixx="0.0033003"
        ixy="0.0019672"
        ixz="-1.2715E-06"
        iyy="0.0012631"
        iyz="2.0564E-06"
        izz="0.0045207" />
    </inertial>
    <visual>
      <origin
        xyz="0 0 0"
        rpy="0 0 0" />
      <geometry>
        <mesh
          filename="package://4090_3.0_2.SLDASM/meshes/LB_SHANK.STL" />
      </geometry>
      <material
        name="">
        <color
          rgba="0.75294 0.75294 0.75294 1" />
      </material>
    </visual>
    <collision>
      <origin
        xyz="0 0 0"
        rpy="0 0 0" />
      <geometry>
        <mesh
          filename="package://4090_3.0_2.SLDASM/meshes/LB_SHANK.STL" />
      </geometry>
    </collision>
  </link>
  <joint
    name="LB_KFE"
    type="revolute">
    <origin
      xyz="-0.16327 -0.11561 0.0835"
      rpy="0 0 0" />
    <parent
      link="LB_THIGH" />
    <child
      link="LB_SHANK" />
    <axis
      xyz="0 0 1" />
    <limit
      lower="-1"
      upper="1"
      effort="80"
      velocity="15.8" />
  </joint>
  <link
    name="LB_FOOT">
    <inertial>
      <origin
        xyz="-0.00024983 -0.0072718 -0.017582"
        rpy="0 0 0" />
      <mass
        value="0.065235" />
      <inertia
        ixx="1.4307E-05"
        ixy="-7.3963E-08"
        ixz="-6.6449E-08"
        iyy="1.25E-05"
        iyz="5.0324E-07"
        izz="1.2857E-05" />
    </inertial>
    <visual>
      <origin
        xyz="0 0 0"
        rpy="0 0 0" />
      <geometry>
        <mesh
          filename="package://4090_3.0_2.SLDASM/meshes/LB_FOOT.STL" />
      </geometry>
      <material
        name="">
        <color
          rgba="0.50196 0.50196 0.75294 1" />
      </material>
    </visual>
    <collision>
      <origin
        xyz="0 0 0"
        rpy="0 0 0" />
      <geometry>
        <mesh
          filename="package://4090_3.0_2.SLDASM/meshes/LB_FOOT.STL" />
      </geometry>
    </collision>
  </link>
  <joint
    name="LB_FIX"
    type="fixed">
    <origin
      xyz="0.15159 -0.25804 0.010893"
      rpy="1.5708 1.5708 0" />
    <parent
      link="LB_SHANK" />
    <child
      link="LB_FOOT" />
    <axis
      xyz="0 0 0" />
  </joint>
</robot>